{
 "cells": [
  {
   "cell_type": "markdown",
   "id": "0cdc6190-882a-4b8e-ae89-dfda87c34f0a",
   "metadata": {},
   "source": [
    "## Assignment_6"
   ]
  },
  {
   "cell_type": "code",
   "execution_count": null,
   "id": "c2afa538-47c9-4880-9719-d3c3ca1b956e",
   "metadata": {},
   "outputs": [],
   "source": [
    "Q1. Describe three applications for exception processing."
   ]
  },
  {
   "cell_type": "code",
   "execution_count": null,
   "id": "1d88676b-c179-4568-9ab2-b812e81e34ce",
   "metadata": {},
   "outputs": [],
   "source": [
    "#Solution:\n",
    "Exception processing, or handling, is a crucial aspect of programming that allows developers to manage unexpected or exceptional situations in their code. Here are three common applications for exception processing:\n",
    "1. Error Handling:\n",
    "- Description: Exception handling is extensively used for managing errors that might occur during the execution of a program. This includes situations such as invalid input, file not found, division by zero, or network errors.\n",
    "- Application: For example, a program that reads data from a file may use exception handling to catch and handle the case where the file is not found. Instead of the program crashing, it can gracefully respond to the error, perhaps by prompting the user to provide a valid file path.\n",
    "2. Resource Management:\n",
    "- Description: Exception processing is often employed to ensure proper resource cleanup, such as closing files, database connections, or network sockets, even if an error occurs during the execution of the program.\n",
    "- Application: Consider a scenario where a program opens a database connection. If an exception occurs during the execution, proper exception handling ensures that the database connection is closed in a finally block, preventing resource leaks and maintaining the integrity of the system.\n",
    "3. Input Validation:\n",
    "- Description: Exception handling can be used to validate input data and respond appropriately when the input does not meet the expected criteria.\n",
    "- Application: In a program that accepts user input, if the input is expected to be a positive integer but the user enters a string or a negative number, exception handling can be used to catch this situation. The program can then prompt the user for valid input or take other corrective actions.\n",
    "These are just a few examples, and exception handling is a versatile tool that can be applied in various scenarios to enhance the robustness and reliability of a program. It allows developers to gracefully handle unexpected situations and provide a more controlled response to errors."
   ]
  },
  {
   "cell_type": "code",
   "execution_count": null,
   "id": "04af6af6-baa5-4870-8f23-fc3e0fc5d4d6",
   "metadata": {},
   "outputs": [],
   "source": [
    "Q2. What happens if you don't do something extra to treat an exception?"
   ]
  },
  {
   "cell_type": "code",
   "execution_count": null,
   "id": "9a637887-8542-4b75-94c2-c010c3efdc20",
   "metadata": {},
   "outputs": [],
   "source": [
    "#Solution:\n",
    "If we don't do something extra to treat an exception, i.e., if we do not handle or catch the exception, the exception will propagate up the call stack. This can have several consequences:\n",
    "1. Program Termination:\n",
    "- If an unhandled exception reaches the top level of the call stack (i.e., it is not caught anywhere in the program), the program will terminate. This often leads to an error message being displayed, and the program's normal execution comes to an abrupt halt.\n",
    "2. Error Message and Stack Trace:\n",
    "- When an unhandled exception occurs, an error message along with a stack trace is usually printed to the console or logged. The stack trace provides information about the sequence of function calls leading up to the point where the exception occurred. This information is valuable for debugging but may expose sensitive details about the program's internals.\n",
    "3. Resource Leaks:\n",
    "- If an exception occurs in a section of code that deals with resource management (e.g., opening files, database connections), resources may not be properly released. This can lead to resource leaks, which may have implications for the overall system's stability and performance.\n",
    "4. Incomplete Operations:\n",
    "If an exception interrupts the execution of a particular operation or transaction, the system may be left in an inconsistent state. For example, if an exception occurs during the processing of a financial transaction, the system might be left with incomplete records.\n",
    "\n",
    "To mitigate these issues, it is essential to implement proper exception handling in your code. This involves using try-except blocks to catch and handle exceptions appropriately. By doing so, we can control the program's response to errors, log relevant information, and potentially recover from exceptional situations without abruptly terminating the program. Handling exceptions is a best practice for writing robust and reliable code."
   ]
  },
  {
   "cell_type": "code",
   "execution_count": null,
   "id": "d6abe08e-d017-43c1-b2fc-15e8f7bc290e",
   "metadata": {},
   "outputs": [],
   "source": [
    "Q3. What are your options for recovering from an exception in your script?"
   ]
  },
  {
   "cell_type": "code",
   "execution_count": null,
   "id": "95eacf9d-cccf-47ad-b3e4-6acf08bcbc75",
   "metadata": {},
   "outputs": [],
   "source": [
    "#Solution:\n",
    "When an exception occurs in a script, we have several options for recovering from it. The appropriate approach depends on the nature of the exception and the requirements of our script. Here are some common strategies for exception recovery:\n",
    "\n",
    "1. Try-Except Block:\n",
    "- Description: Use a try-except block to catch and handle specific exceptions.\n",
    "Example:\n",
    "try:\n",
    "    # code that may raise an exception\n",
    "except SomeSpecificException as e:\n",
    "    # handle the specific exception\n",
    "except AnotherException as e:\n",
    "    # handle another specific exception\n",
    "else:\n",
    "    # optional block that runs if no exception occurs\n",
    "finally:\n",
    "    # optional block that always runs, useful for cleanup\n",
    "\n",
    "2. Logging and Reporting:\n",
    "- Description: Log information about the exception and report it for later analysis.\n",
    "Example:\n",
    "import logging\n",
    "\n",
    "try:\n",
    "    # code that may raise an exception\n",
    "except Exception as e:\n",
    "    logging.exception(\"An error occurred: %s\", str(e))\n",
    "    # other exception handling code\n",
    "\n",
    "3. Graceful Degradation:\n",
    "- Description: Design the script to gracefully degrade its functionality in the face of certain exceptions.\n",
    "Example:\n",
    "try:\n",
    "    # code that may raise an exception\n",
    "except SomeCriticalException as e:\n",
    "    # handle the critical exception, and continue with reduced functionality\n",
    "\n",
    "4. Retrying Operations:\n",
    "- Description: Retry the operation that raised the exception.\n",
    "Example:\n",
    "max_retries = 3\n",
    "retries = 0\n",
    "\n",
    "while retries < max_retries:\n",
    "    try:\n",
    "        # code that may raise an exception\n",
    "        break  # break out of the loop if successful\n",
    "    except SomeTransientException as e:\n",
    "        # handle the transient exception\n",
    "        retries += 1\n",
    "5. Custom Exception Classes:\n",
    "- Description: Define custom exception classes for specific error scenarios and catch them in our code.\n",
    "Example:\n",
    "class CustomError(Exception):\n",
    "    pass\n",
    "\n",
    "try:\n",
    "    # code that may raise CustomError\n",
    "except CustomError as e:\n",
    "    # handle the custom exception\n",
    "\n",
    "6. Clean Up Resources:\n",
    "- Description: Use the finally block to ensure that resources are properly cleaned up, regardless of whether an exception occurred.\n",
    "Example:\n",
    "try:\n",
    "    # code that may raise an exception\n",
    "finally:\n",
    "    # cleanup code (e.g., close files, release resources)\n",
    "\n",
    "The specific recovery strategy depends on the goals of our script and the nature of the exceptions it may encounter. It's often a good practice to handle exceptions as close to where they occur as possible and to provide informative error messages or logs for debugging and analysis."
   ]
  },
  {
   "cell_type": "code",
   "execution_count": null,
   "id": "30909c4a-729d-4e0c-bd43-7e976a4dce63",
   "metadata": {},
   "outputs": [],
   "source": [
    "Q4. Describe two methods for triggering exceptions in your script."
   ]
  },
  {
   "cell_type": "code",
   "execution_count": null,
   "id": "1eb8ed5b-f993-4c53-b3d5-07bede55ffee",
   "metadata": {},
   "outputs": [],
   "source": [
    "#Solution:\n",
    "In Python, there are various ways to intentionally trigger exceptions in our script. Triggering exceptions can be useful for testing error-handling mechanisms or for signaling specific conditions. Here are two common methods:\n",
    "1. Raise Statement:\n",
    "- Description: The raise statement is used to raise an exception manually. we can use it to trigger built-in exceptions or create custom exceptions.\n",
    "Example:\n",
    "def divide(x, y):\n",
    "    if y == 0:\n",
    "        raise ValueError(\"Division by zero is not allowed\")\n",
    "    return x / y\n",
    "\n",
    "try:\n",
    "    result = divide(10, 0)\n",
    "except ValueError as e:\n",
    "    print(f\"Exception caught: {e}\")\n",
    "\n",
    "In this example, the divide function raises a ValueError exception when attempting to divide by zero. The raise statement allows us to trigger exceptions at specific points in our code.\n",
    "\n",
    "2. Assert Statement:\n",
    "- Description: The assert statement is used to test a condition, and if the condition is False, it raises an AssertionError exception. While primarily used for debugging and testing, it can also be used to signal unexpected conditions.\n",
    "Example:\n",
    "def process_data(data):\n",
    "    assert isinstance(data, list), \"Input must be a list\"\n",
    "    # rest of the code processing the list\n",
    "\n",
    "try:\n",
    "    process_data(\"not a list\")\n",
    "except AssertionError as e:\n",
    "    print(f\"AssertionError caught: {e}\")\n",
    "\n",
    "Here, the process_data function asserts that the input is a list. If the condition is not met, an AssertionError is raised. This can be a way to explicitly state assumptions about our code and trigger exceptions if those assumptions are violated.\n",
    "These methods allow us to deliberately introduce exceptions into our code, helping us verify that our error-handling mechanisms are working as expected and that our program responds appropriately to exceptional conditions."
   ]
  },
  {
   "cell_type": "code",
   "execution_count": null,
   "id": "ac786760-b777-4ce1-bdfe-e93b1d903140",
   "metadata": {},
   "outputs": [],
   "source": [
    "Q5. Identify two methods for specifying actions to be executed at termination time, regardless of\n",
    "whether or not an exception exists."
   ]
  },
  {
   "cell_type": "code",
   "execution_count": null,
   "id": "3086833b-c9e2-4da9-a770-f8f96dea83b8",
   "metadata": {},
   "outputs": [],
   "source": [
    "#Solution:\n",
    "In Python, we can use the finally block and the atexit module to specify actions that should be executed at termination time, regardless of whether or not an exception occurred. These methods ensure that certain code is run even if an exception is raised or not. Here's an explanation of both:\n",
    "\n",
    "1. Using finally Block:\n",
    "- Description: The finally block is used in conjunction with the try and except blocks. The code inside the finally block is executed no matter what, whether an exception is raised or not.\n",
    "Example:\n",
    "\n",
    "try:\n",
    "    # Code that may raise an exception\n",
    "    result = 10 / 0\n",
    "except ZeroDivisionError:\n",
    "    print(\"Cannot divide by zero\")\n",
    "finally:\n",
    "    print(\"This will always be executed, with or without an exception\")\n",
    "\n",
    "In this example, even though a ZeroDivisionError occurs, the code inside the finally block will be executed.\n",
    "\n",
    "2. Using atexit Module:\n",
    "- Description: The atexit module provides a way to register functions to be called when a program is closing down. These functions are executed regardless of whether the program exits normally or due to an unhandled exception.\n",
    "Example:\n",
    "\n",
    "import atexit\n",
    "\n",
    "def exit_handler():\n",
    "    print(\"This will be executed at program termination\")\n",
    "\n",
    "# Registering the exit_handler function\n",
    "atexit.register(exit_handler)\n",
    "\n",
    "# Code that may raise an exception\n",
    "result = 10 / 0\n",
    "\n",
    "\n"
   ]
  }
 ],
 "metadata": {
  "kernelspec": {
   "display_name": "Python 3 (ipykernel)",
   "language": "python",
   "name": "python3"
  },
  "language_info": {
   "codemirror_mode": {
    "name": "ipython",
    "version": 3
   },
   "file_extension": ".py",
   "mimetype": "text/x-python",
   "name": "python",
   "nbconvert_exporter": "python",
   "pygments_lexer": "ipython3",
   "version": "3.10.6"
  }
 },
 "nbformat": 4,
 "nbformat_minor": 5
}
